Workbook
Name _cao1: #REF!
Name _cao2: #REF!
Name _cao3: #REF!
Name _cao4: #REF!
Name _cao5: #REF!
Name _cao6: #REF!
Name _dai1: #REF!
Name _dai2: #REF!
Name _dai3: #REF!
Name _dai4: #REF!
Name _dai5: #REF!
Name _dai6: #REF!
Name _dan1: #REF!
Name _dan2: #REF!
Name _KDX3: #N/A
Name _phi10: #REF!
Name _phi12: #REF!
Name _phi14: #REF!
Name _phi16: #REF!
Name _phi18: #REF!
Name _phi20: #REF!
Name _phi22: #REF!
Name _phi25: #REF!
Name _phi28: #REF!
Name _phi6: #REF!
Name _phi8: #REF!
Name _slg1: #REF!
Name _slg2: #REF!
Name _slg3: #REF!
Name _slg4: #REF!
Name _slg5: #REF!
Name _slg6: #REF!
Name _tam1: [2]XL4Poppy!$C$31
Name _XDo100: '[3]DG 285'!$B$236
Name _XDo140: '[3]DG 285'!$B$237
Name _XDo230: '[3]DG 285'!$B$238
Name _XDo25: '[3]DG 285'!$B$234
Name _XDo320: '[3]DG 285'!$B$239
Name _XDo50: '[3]DG 285'!$B$235
Name a: #REF!
Name an: '[4]M6A-208 Steering dust'!#REF!
Name anhung2: {"th152.xls"}
Name Aptomat: '[3]DG 286'!$A$90:$G$155
Name AQ: #REF!
Name b: #REF!
Name b1_: #REF!
Name b2_: #REF!
Name b3_: #REF!
Name b4_: #REF!
Name bangchu: #REF!
Name BDTC_285: '[3]DG 285'!$A$59:$G$119
Name bengam: #REF!
Name benuoc: #REF!
Name c_: #REF!
Name CACAU: 325976
Name cao: #REF!
Name capduong: #REF!
Name cdhrht: [5]CPKS_TK!#REF!
Name Choices_Wrapper: #N/A
Name CLAIM: 3

Sheet DMVT
X1: BẢNG ĐỊNH MỨC GIA CÔNG JIG ĐỘT LỖ CẢN SAU XE AI3-NM LINH KIỆN NHỰA | AP1: Vấn đề chung
X2: HẠNG MỤC/ĐƠN HÀNG SỐ:
A3: STT | B3: MSCT | C3: Tên chi tiết | D3: Vật liệu | E3: Quy cách chi tiết (mm) | J3: SL/Bộ | K3: SL/ĐH | L3: Khối lượng | O3: NMT | P3: NMK | Q3: THCK | AJ3: Nguồn gốc/ Mua ngoài | AM3: Màu sơn/ Mã màu sơn | AN3: Diện tích sơn,ED (m²) | AO3: Ghi chú | AP3: Các bộ phận triển khai ĐMVT giữ nguyên mẫu
E4: Dài | F4: Rộng | G4: Dày | H4: Dn | I4: Dt | Q4: X. Hàn | AB4: X. SƠN | AF4: X. Lắp Ráp | AH4: VCNB THCK | AI4: Đội lắp đặt
L5: KL/ct (Kg) | M5: KL/Bộ (Kg) | N5: Tổng KL/ĐH (Kg) | Q5: X. HÀN LK Cơ Khí Ô Tô | W5: X.Hàn Gia công Cơ khí | AP5: Số thứ tự theo ĐMVT tổng | AQ5: Đặt NMT | AR5: Đặt NMK
Q6: Hàn LK Tải / Bus | R6: Hàn KX Ghế | S6: Hàn Ty ben | T6: Hàn Ống xả | U6: Hàn Thùng | V6: Hàn Chasis | W6: Hàn TBCN | X6: Hàn kim loại màu | Y6: Lốc/Uốn CKXD | Z6: Hàn CKXD | AA6: Phun bi CKXD | AB6: Mạ | AC6: ED | AD6: Sơn màu | AE6: Sơn TĐ bột | AF6: Lắp ráp TBCN (Sub) | AG6: Lắp ráp thùng | AH6: Kho giao hàng | AJ6: NMT | AK6: NMK | AL6: THCK
K7: =J7 -> 0 | L7: =IFERROR((IFERROR(IF(MID(F7,3,1)="x",(LEFT(F7,2)*2+RIGHT(F7,2)*2-2*4*G7)*G7*E7*VLOOKUP(D7,'KL RIENG'!$B$3:$C$1048576,2,0)*10^-6,IF(AND(H7<>0,I7="",G7=""),H7*H7*E7*3.14/4*VLOOKUP(D7,'KL RIENG'!$B$3:$C$1048576,2,0)*10^-6,IF(AND(H7<>"",I7 ="",G7<>"",E7=""),H7*H7*G7*VLOOKUP(D7,'KL RIENG'!$B$3:$C$1048576,2,0)*10^-6,IF(AND(H7<>"",I7<>"",G7<>"",E7=""),H7*H7*G7*VLOOKUP(D7,'KL RIENG'!$B$3:$C$1048576,2,0)*10^-6,IF(AND(H7<>0,I7<>0,G7=""),(H7*H7-I7*I7)*3.14*E7/4*VLOOKUP(D7,'KL RIENG'!$B$3:$C$1048576,2,0)*10^-6,IF(AND(G7<>0,H7<>0,I7=""),(H7*H7-((H7-2*G7)*(H7-2*G7)))*3.14*E7/4*VLOOKUP(D7,'KL RIENG'!$B$3:$C$1048576,2,0)*10^-6,G7*F7*E7*VLOOKUP(D7,'KL RIENG'!$B$3:$C$1048576,2,0)*10^-6)))))),VLOOKUP(F7,'THEP HINH'!$B$4:$E$1048576,3,0)*DMVT!E7*VLOOKUP(D7,'KL RIENG'!$B$3:$C$1048576,2,0)*10^-6)),"") | M7: =IFERROR(J7*L7,"") | N7: =L7*K7 -> #VALUE! | AP7: 3 | AQ7: =IF(LEN(CONCATENATE(O7))>0,"X","") | AR7: =IF(LEN(CONCATENATE(P7))>0,"X","")
K8: =J8 -> 0 | L8: =IFERROR((IFERROR(IF(MID(F8,3,1)="x",(LEFT(F8,2)*2+RIGHT(F8,2)*2-2*4*G8)*G8*E8*VLOOKUP(D8,'KL RIENG'!$B$3:$C$1048576,2,0)*10^-6,IF(AND(H8<>0,I8="",G8=""),H8*H8*E8*3.14/4*VLOOKUP(D8,'KL RIENG'!$B$3:$C$1048576,2,0)*10^-6,IF(AND(H8<>"",I8 ="",G8<>"",E8=""),H8*H8*G8*VLOOKUP(D8,'KL RIENG'!$B$3:$C$1048576,2,0)*10^-6,IF(AND(H8<>"",I8<>"",G8<>"",E8=""),H8*H8*G8*VLOOKUP(D8,'KL RIENG'!$B$3:$C$1048576,2,0)*10^-6,IF(AND(H8<>0,I8<>0,G8=""),(H8*H8-I8*I8)*3.14*E8/4*VLOOKUP(D8,'KL RIENG'!$B$3:$C$1048576,2,0)*10^-6,IF(AND(G8<>0,H8<>0,I8=""),(H8*H8-((H8-2*G8)*(H8-2*G8)))*3.14*E8/4*VLOOKUP(D8,'KL RIENG'!$B$3:$C$1048576,2,0)*10^-6,G8*F8*E8*VLOOKUP(D8,'KL RIENG'!$B$3:$C$1048576,2,0)*10^-6)))))),VLOOKUP(F8,'THEP HINH'!$B$4:$E$1048576,3,0)*DMVT!E8*VLOOKUP(D8,'KL RIENG'!$B$3:$C$1048576,2,0)*10^-6)),"") | M8: =IFERROR(J8*L8,"") | N8: =L8*K8 -> #VALUE! | AP8: 4 | AQ8: =IF(LEN(CONCATENATE(O8))>0,"X","") | AR8: =IF(LEN(CONCATENATE(P8))>0,"X","")
K9: =J9 -> 0 | L9: =IFERROR((IFERROR(IF(MID(F9,3,1)="x",(LEFT(F9,2)*2+RIGHT(F9,2)*2-2*4*G9)*G9*E9*VLOOKUP(D9,'KL RIENG'!$B$3:$C$1048576,2,0)*10^-6,IF(AND(H9<>0,I9="",G9=""),H9*H9*E9*3.14/4*VLOOKUP(D9,'KL RIENG'!$B$3:$C$1048576,2,0)*10^-6,IF(AND(H9<>"",I9 ="",G9<>"",E9=""),H9*H9*G9*VLOOKUP(D9,'KL RIENG'!$B$3:$C$1048576,2,0)*10^-6,IF(AND(H9<>"",I9<>"",G9<>"",E9=""),H9*H9*G9*VLOOKUP(D9,'KL RIENG'!$B$3:$C$1048576,2,0)*10^-6,IF(AND(H9<>0,I9<>0,G9=""),(H9*H9-I9*I9)*3.14*E9/4*VLOOKUP(D9,'KL RIENG'!$B$3:$C$1048576,2,0)*10^-6,IF(AND(G9<>0,H9<>0,I9=""),(H9*H9-((H9-2*G9)*(H9-2*G9)))*3.14*E9/4*VLOOKUP(D9,'KL RIENG'!$B$3:$C$1048576,2,0)*10^-6,G9*F9*E9*VLOOKUP(D9,'KL RIENG'!$B$3:$C$1048576,2,0)*10^-6)))))),VLOOKUP(F9,'THEP HINH'!$B$4:$E$1048576,3,0)*DMVT!E9*VLOOKUP(D9,'KL RIENG'!$B$3:$C$1048576,2,0)*10^-6)),"") | M9: =IFERROR(J9*L9,"") | N9: =L9*K9 -> #VALUE! | AP9: 5 | AQ9: =IF(LEN(CONCATENATE(O9))>0,"X","") | AR9: =IF(LEN(CONCATENATE(P9))>0,"X","")
K10: =J10 -> 0 | L10: =IFERROR((IFERROR(IF(MID(F10,3,1)="x",(LEFT(F10,2)*2+RIGHT(F10,2)*2-2*4*G10)*G10*E10*VLOOKUP(D10,'KL RIENG'!$B$3:$C$1048576,2,0)*10^-6,IF(AND(H10<>0,I10="",G10=""),H10*H10*E10*3.14/4*VLOOKUP(D10,'KL RIENG'!$B$3:$C$1048576,2,0)*10^-6,IF(AND(H10<>"",I10 ="",G10<>"",E10=""),H10*H10*G10*VLOOKUP(D10,'KL RIENG'!$B$3:$C$1048576,2,0)*10^-6,IF(AND(H10<>"",I10<>"",G10<>"",E10=""),H10*H10*G10*VLOOKUP(D10,'KL RIENG'!$B$3:$C$1048576,2,0)*10^-6,IF(AND(H10<>0,I10<>0,G10=""),(H10*H10-I10*I10)*3.14*E10/4*VLOOKUP(D10,'KL RIENG'!$B$3:$C$1048576,2,0)*10^-6,IF(AND(G10<>0,H10<>0,I10=""),(H10*H10-((H10-2*G10)*(H10-2*G10)))*3.14*E10/4*VLOOKUP(D10,'KL RIENG'!$B$3:$C$1048576,2,0)*10^-6,G10*F10*E10*VLOOKUP(D10,'KL RIENG'!$B$3:$C$1048576,2,0)*10^-6)))))),VLOOKUP(F10,'THEP HINH'!$B$4:$E$1048576,3,0)*DMVT!E10*VLOOKUP(D10,'KL RIENG'!$B$3:$C$1048576,2,0)*10^-6)),"") | M10: =IFERROR(J10*L10,"") | N10: =L10*K10 -> #VALUE! | AP10: 6 | AQ10: =IF(LEN(CONCATENATE(O10))>0,"X","") | AR10: =IF(LEN(CONCATENATE(P10))>0,"X","")
K11: =J11 -> 0 | L11: =IFERROR((IFERROR(IF(MID(F11,3,1)="x",(LEFT(F11,2)*2+RIGHT(F11,2)*2-2*4*G11)*G11*E11*VLOOKUP(D11,'KL RIENG'!$B$3:$C$1048576,2,0)*10^-6,IF(AND(H11<>0,I11="",G11=""),H11*H11*E11*3.14/4*VLOOKUP(D11,'KL RIENG'!$B$3:$C$1048576,2,0)*10^-6,IF(AND(H11<>"",I11 ="",G11<>"",E11=""),H11*H11*G11*VLOOKUP(D11,'KL RIENG'!$B$3:$C$1048576,2,0)*10^-6,IF(AND(H11<>"",I11<>"",G11<>"",E11=""),H11*H11*G11*VLOOKUP(D11,'KL RIENG'!$B$3:$C$1048576,2,0)*10^-6,IF(AND(H11<>0,I11<>0,G11=""),(H11*H11-I11*I11)*3.14*E11/4*VLOOKUP(D11,'KL RIENG'!$B$3:$C$1048576,2,0)*10^-6,IF(AND(G11<>0,H11<>0,I11=""),(H11*H11-((H11-2*G11)*(H11-2*G11)))*3.14*E11/4*VLOOKUP(D11,'KL RIENG'!$B$3:$C$1048576,2,0)*10^-6,G11*F11*E11*VLOOKUP(D11,'KL RIENG'!$B$3:$C$1048576,2,0)*10^-6)))))),VLOOKUP(F11,'THEP HINH'!$B$4:$E$1048576,3,0)*DMVT!E11*VLOOKUP(D11,'KL RIENG'!$B$3:$C$1048576,2,0)*10^-6)),"") | M11: =IFERROR(J11*L11,"") | N11: =L11*K11 -> #VALUE! | AP11: 7 | AQ11: =IF(LEN(CONCATENATE(O11))>0,"X","") | AR11: =IF(LEN(CONCATENATE(P11))>0,"X","")
K12: =J12 -> 0 | L12: =IFERROR((IFERROR(IF(MID(F12,3,1)="x",(LEFT(F12,2)*2+RIGHT(F12,2)*2-2*4*G12)*G12*E12*VLOOKUP(D12,'KL RIENG'!$B$3:$C$1048576,2,0)*10^-6,IF(AND(H12<>0,I12="",G12=""),H12*H12*E12*3.14/4*VLOOKUP(D12,'KL RIENG'!$B$3:$C$1048576,2,0)*10^-6,IF(AND(H12<>"",I12 ="",G12<>"",E12=""),H12*H12*G12*VLOOKUP(D12,'KL RIENG'!$B$3:$C$1048576,2,0)*10^-6,IF(AND(H12<>"",I12<>"",G12<>"",E12=""),H12*H12*G12*VLOOKUP(D12,'KL RIENG'!$B$3:$C$1048576,2,0)*10^-6,IF(AND(H12<>0,I12<>0,G12=""),(H12*H12-I12*I12)*3.14*E12/4*VLOOKUP(D12,'KL RIENG'!$B$3:$C$1048576,2,0)*10^-6,IF(AND(G12<>0,H12<>0,I12=""),(H12*H12-((H12-2*G12)*(H12-2*G12)))*3.14*E12/4*VLOOKUP(D12,'KL RIENG'!$B$3:$C$1048576,2,0)*10^-6,G12*F12*E12*VLOOKUP(D12,'KL RIENG'!$B$3:$C$1048576,2,0)*10^-6)))))),VLOOKUP(F12,'THEP HINH'!$B$4:$E$1048576,3,0)*DMVT!E12*VLOOKUP(D12,'KL RIENG'!$B$3:$C$1048576,2,0)*10^-6)),"") | M12: =IFERROR(J12*L12,"") | N12: =L12*K12 -> #VALUE! | AP12: 8 | AQ12: =IF(LEN(CONCATENATE(O12))>0,"X","") | AR12: =IF(LEN(CONCATENATE(P12))>0,"X","")
K13: =J13 -> 0 | L13: =IFERROR((IFERROR(IF(MID(F13,3,1)="x",(LEFT(F13,2)*2+RIGHT(F13,2)*2-2*4*G13)*G13*E13*VLOOKUP(D13,'KL RIENG'!$B$3:$C$1048576,2,0)*10^-6,IF(AND(H13<>0,I13="",G13=""),H13*H13*E13*3.14/4*VLOOKUP(D13,'KL RIENG'!$B$3:$C$1048576,2,0)*10^-6,IF(AND(H13<>"",I13 ="",G13<>"",E13=""),H13*H13*G13*VLOOKUP(D13,'KL RIENG'!$B$3:$C$1048576,2,0)*10^-6,IF(AND(H13<>"",I13<>"",G13<>"",E13=""),H13*H13*G13*VLOOKUP(D13,'KL RIENG'!$B$3:$C$1048576,2,0)*10^-6,IF(AND(H13<>0,I13<>0,G13=""),(H13*H13-I13*I13)*3.14*E13/4*VLOOKUP(D13,'KL RIENG'!$B$3:$C$1048576,2,0)*10^-6,IF(AND(G13<>0,H13<>0,I13=""),(H13*H13-((H13-2*G13)*(H13-2*G13)))*3.14*E13/4*VLOOKUP(D13,'KL RIENG'!$B$3:$C$1048576,2,0)*10^-6,G13*F13*E13*VLOOKUP(D13,'KL RIENG'!$B$3:$C$1048576,2,0)*10^-6)))))),VLOOKUP(F13,'THEP HINH'!$B$4:$E$1048576,3,0)*DMVT!E13*VLOOKUP(D13,'KL RIENG'!$B$3:$C$1048576,2,0)*10^-6)),"") | M13: =IFERROR(J13*L13,"") | N13: =L13*K13 -> #VALUE! | AP13: 9 | AQ13: =IF(LEN(CONCATENATE(O13))>0,"X","") | AR13: =IF(LEN(CONCATENATE(P13))>0,"X","")
K14: =J14 -> 0 | L14: =IFERROR((IFERROR(IF(MID(F14,3,1)="x",(LEFT(F14,2)*2+RIGHT(F14,2)*2-2*4*G14)*G14*E14*VLOOKUP(D14,'KL RIENG'!$B$3:$C$1048576,2,0)*10^-6,IF(AND(H14<>0,I14="",G14=""),H14*H14*E14*3.14/4*VLOOKUP(D14,'KL RIENG'!$B$3:$C$1048576,2,0)*10^-6,IF(AND(H14<>"",I14 ="",G14<>"",E14=""),H14*H14*G14*VLOOKUP(D14,'KL RIENG'!$B$3:$C$1048576,2,0)*10^-6,IF(AND(H14<>"",I14<>"",G14<>"",E14=""),H14*H14*G14*VLOOKUP(D14,'KL RIENG'!$B$3:$C$1048576,2,0)*10^-6,IF(AND(H14<>0,I14<>0,G14=""),(H14*H14-I14*I14)*3.14*E14/4*VLOOKUP(D14,'KL RIENG'!$B$3:$C$1048576,2,0)*10^-6,IF(AND(G14<>0,H14<>0,I14=""),(H14*H14-((H14-2*G14)*(H14-2*G14)))*3.14*E14/4*VLOOKUP(D14,'KL RIENG'!$B$3:$C$1048576,2,0)*10^-6,G14*F14*E14*VLOOKUP(D14,'KL RIENG'!$B$3:$C$1048576,2,0)*10^-6)))))),VLOOKUP(F14,'THEP HINH'!$B$4:$E$1048576,3,0)*DMVT!E14*VLOOKUP(D14,'KL RIENG'!$B$3:$C$1048576,2,0)*10^-6)),"") | M14: =IFERROR(J14*L14,"") | N14: =L14*K14 -> #VALUE! | AP14: 10 | AQ14: =IF(LEN(CONCATENATE(O14))>0,"X","") | AR14: =IF(LEN(CONCATENATE(P14))>0,"X","")
K15: =J15 -> 0 | L15: =IFERROR((IFERROR(IF(MID(F15,3,1)="x",(LEFT(F15,2)*2+RIGHT(F15,2)*2-2*4*G15)*G15*E15*VLOOKUP(D15,'KL RIENG'!$B$3:$C$1048576,2,0)*10^-6,IF(AND(H15<>0,I15="",G15=""),H15*H15*E15*3.14/4*VLOOKUP(D15,'KL RIENG'!$B$3:$C$1048576,2,0)*10^-6,IF(AND(H15<>"",I15 ="",G15<>"",E15=""),H15*H15*G15*VLOOKUP(D15,'KL RIENG'!$B$3:$C$1048576,2,0)*10^-6,IF(AND(H15<>"",I15<>"",G15<>"",E15=""),H15*H15*G15*VLOOKUP(D15,'KL RIENG'!$B$3:$C$1048576,2,0)*10^-6,IF(AND(H15<>0,I15<>0,G15=""),(H15*H15-I15*I15)*3.14*E15/4*VLOOKUP(D15,'KL RIENG'!$B$3:$C$1048576,2,0)*10^-6,IF(AND(G15<>0,H15<>0,I15=""),(H15*H15-((H15-2*G15)*(H15-2*G15)))*3.14*E15/4*VLOOKUP(D15,'KL RIENG'!$B$3:$C$1048576,2,0)*10^-6,G15*F15*E15*VLOOKUP(D15,'KL RIENG'!$B$3:$C$1048576,2,0)*10^-6)))))),VLOOKUP(F15,'THEP HINH'!$B$4:$E$1048576,3,0)*DMVT!E15*VLOOKUP(D15,'KL RIENG'!$B$3:$C$1048576,2,0)*10^-6)),"") | M15: =IFERROR(J15*L15,"") | N15: =L15*K15 -> #VALUE! | AP15: 8 | AQ15: =IF(LEN(CONCATENATE(O15))>0,"X","") | AR15: =IF(LEN(CONCATENATE(P15))>0,"X","")
K16: =J16 -> 0 | L16: =IFERROR((IFERROR(IF(MID(F16,3,1)="x",(LEFT(F16,2)*2+RIGHT(F16,2)*2-2*4*G16)*G16*E16*VLOOKUP(D16,'KL RIENG'!$B$3:$C$1048576,2,0)*10^-6,IF(AND(H16<>0,I16="",G16=""),H16*H16*E16*3.14/4*VLOOKUP(D16,'KL RIENG'!$B$3:$C$1048576,2,0)*10^-6,IF(AND(H16<>"",I16 ="",G16<>"",E16=""),H16*H16*G16*VLOOKUP(D16,'KL RIENG'!$B$3:$C$1048576,2,0)*10^-6,IF(AND(H16<>"",I16<>"",G16<>"",E16=""),H16*H16*G16*VLOOKUP(D16,'KL RIENG'!$B$3:$C$1048576,2,0)*10^-6,IF(AND(H16<>0,I16<>0,G16=""),(H16*H16-I16*I16)*3.14*E16/4*VLOOKUP(D16,'KL RIENG'!$B$3:$C$1048576,2,0)*10^-6,IF(AND(G16<>0,H16<>0,I16=""),(H16*H16-((H16-2*G16)*(H16-2*G16)))*3.14*E16/4*VLOOKUP(D16,'KL RIENG'!$B$3:$C$1048576,2,0)*10^-6,G16*F16*E16*VLOOKUP(D16,'KL RIENG'!$B$3:$C$1048576,2,0)*10^-6)))))),VLOOKUP(F16,'THEP HINH'!$B$4:$E$1048576,3,0)*DMVT!E16*VLOOKUP(D16,'KL RIENG'!$B$3:$C$1048576,2,0)*10^-6)),"") | M16: =IFERROR(J16*L16,"") | N16: =L16*K16 -> #VALUE! | AP16: 32 | AQ16: =IF(LEN(CONCATENATE(O16))>0,"X","") | AR16: =IF(LEN(CONCATENATE(P16))>0,"X","")
K17: =J17 -> 0 | L17: =IFERROR((IFERROR(IF(MID(F17,3,1)="x",(LEFT(F17,2)*2+RIGHT(F17,2)*2-2*4*G17)*G17*E17*VLOOKUP(D17,'KL RIENG'!$B$3:$C$1048576,2,0)*10^-6,IF(AND(H17<>0,I17="",G17=""),H17*H17*E17*3.14/4*VLOOKUP(D17,'KL RIENG'!$B$3:$C$1048576,2,0)*10^-6,IF(AND(H17<>"",I17 ="",G17<>"",E17=""),H17*H17*G17*VLOOKUP(D17,'KL RIENG'!$B$3:$C$1048576,2,0)*10^-6,IF(AND(H17<>"",I17<>"",G17<>"",E17=""),H17*H17*G17*VLOOKUP(D17,'KL RIENG'!$B$3:$C$1048576,2,0)*10^-6,IF(AND(H17<>0,I17<>0,G17=""),(H17*H17-I17*I17)*3.14*E17/4*VLOOKUP(D17,'KL RIENG'!$B$3:$C$1048576,2,0)*10^-6,IF(AND(G17<>0,H17<>0,I17=""),(H17*H17-((H17-2*G17)*(H17-2*G17)))*3.14*E17/4*VLOOKUP(D17,'KL RIENG'!$B$3:$C$1048576,2,0)*10^-6,G17*F17*E17*VLOOKUP(D17,'KL RIENG'!$B$3:$C$1048576,2,0)*10^-6)))))),VLOOKUP(F17,'THEP HINH'!$B$4:$E$1048576,3,0)*DMVT!E17*VLOOKUP(D17,'KL RIENG'!$B$3:$C$1048576,2,0)*10^-6)),"") | M17: =IFERROR(J17*L17,"") | N17: =L17*K17 -> #VALUE! | AP17: 33 | AQ17: =IF(LEN(CONCATENATE(O17))>0,"X","") | AR17: =IF(LEN(CONCATENATE(P17))>0,"X","")
K18: =J18 -> 0 | L18: =IFERROR((IFERROR(IF(MID(F18,3,1)="x",(LEFT(F18,2)*2+RIGHT(F18,2)*2-2*4*G18)*G18*E18*VLOOKUP(D18,'KL RIENG'!$B$3:$C$1048576,2,0)*10^-6,IF(AND(H18<>0,I18="",G18=""),H18*H18*E18*3.14/4*VLOOKUP(D18,'KL RIENG'!$B$3:$C$1048576,2,0)*10^-6,IF(AND(H18<>"",I18 ="",G18<>"",E18=""),H18*H18*G18*VLOOKUP(D18,'KL RIENG'!$B$3:$C$1048576,2,0)*10^-6,IF(AND(H18<>"",I18<>"",G18<>"",E18=""),H18*H18*G18*VLOOKUP(D18,'KL RIENG'!$B$3:$C$1048576,2,0)*10^-6,IF(AND(H18<>0,I18<>0,G18=""),(H18*H18-I18*I18)*3.14*E18/4*VLOOKUP(D18,'KL RIENG'!$B$3:$C$1048576,2,0)*10^-6,IF(AND(G18<>0,H18<>0,I18=""),(H18*H18-((H18-2*G18)*(H18-2*G18)))*3.14*E18/4*VLOOKUP(D18,'KL RIENG'!$B$3:$C$1048576,2,0)*10^-6,G18*F18*E18*VLOOKUP(D18,'KL RIENG'!$B$3:$C$1048576,2,0)*10^-6)))))),VLOOKUP(F18,'THEP HINH'!$B$4:$E$1048576,3,0)*DMVT!E18*VLOOKUP(D18,'KL RIENG'!$B$3:$C$1048576,2,0)*10^-6)),"") | M18: =IFERROR(J18*L18,"") | N18: =L18*K18 -> #VALUE! | AP18: 34 | AQ18: =IF(LEN(CONCATENATE(O18))>0,"X","") | AR18: =IF(LEN(CONCATENATE(P18))>0,"X","")
... K36: =J36 -> 0 | L36: =IFERROR((IFERROR(IF(MID(F36,3,1)="x",(LEFT(F36,2)*2+RIGHT(F36,2)*2-2*4*G36)*G36*E36*VLOOKUP(D36,'KL RIENG'!$B$3:$C$1048576,2,0)*10^-6,IF(AND(H36<>0,I36="",G36=""),H36*H36*E36*3.14/4*VLOOKUP(D36,'KL RIENG'!$B$3:$C$1048576,2,0)*10^-6,IF(AND(H36<>"",I36 ="",G36<>"",E36=""),H36*H36*G36*VLOOKUP(D36,'KL RIENG'!$B$3:$C$1048576,2,0)*10^-6,IF(AND(H36<>"",I36<>"",G36<>"",E36=""),H36*H36*G36*VLOOKUP(D36,'KL RIENG'!$B$3:$C$1048576,2,0)*10^-6,IF(AND(H36<>0,I36<>0,G36=""),(H36*H36-I36*I36)*3.14*E36/4*VLOOKUP(D36,'KL RIENG'!$B$3:$C$1048576,2,0)*10^-6,IF(AND(G36<>0,H36<>0,I36=""),(H36*H36-((H36-2*G36)*(H36-2*G36)))*3.14*E36/4*VLOOKUP(D36,'KL RIENG'!$B$3:$C$1048576,2,0)*10^-6,G36*F36*E36*VLOOKUP(D36,'KL RIENG'!$B$3:$C$1048576,2,0)*10^-6)))))),VLOOKUP(F36,'THEP HINH'!$B$4:$E$1048576,3,0)*DMVT!E36*VLOOKUP(D36,'KL RIENG'!$B$3:$C$1048576,2,0)*10^-6)),"") | M36: =IFERROR(J36*L36,"") | N36: =L36*K36 -> #VALUE! | AP36: 37 | AQ36: =IF(LEN(CONCATENATE(O36))>0,"X","") | AR36: =IF(LEN(CONCATENATE(P36))>0,"X","")
A37: Tổng cộng | N37: =SUM(N7:N21) -> #VALUE!

Sheet KL RIENG
A1: KHỐI LƯỢNG RIÊNG VẬT LIỆU
A2: STT | B2: VẬT LIỆU | C2: KL RIÊNG (kg/dm3)
A3: I | B3: THÉP
A4: 1 | B4: SPHC | C4: 7.85
A5: =+A4+1 -> 2 | B5: SPCC | C5: 7.85
A6: =+A5+1 -> 3 | B6: SS400 | C6: 7.85
A7: =+A6+1 -> 4 | B7: C45 | C7: 7.85
A8: =+A7+1 -> 5 | B8: CT380 | C8: 7.85
A9: =+A8+1 -> 6 | B9: SKD11 | C9: 7.85
A10: =+A9+1 -> 7 | B10: SKD61 | C10: 7.85
A11: =+A10+1 -> 8 | B11: Tôn màu trắng | C11: 7.93 | I11: 36301.34 | J11: 36260.347 | K11: 36260.347 | M11: 36260.347 | N11: 36260.347
A12: =+A11+1 -> 9 | B12: Tôn gân | C12: 7.93 | I12: 36301.34 | J12: 36260.347 | K12: 36260.347 | M12: 36260.347 | N12: 36260.347
A13: =+A10+1 -> 8 | B13: Mạ kẽm | C13: 7.85 | M13: 34194.858 | N13: 34194.858 | R13: 2790 | S13: 1400000000
A14: =+A10+1 -> 8 | B14: Thép vằn | C14: 7.85 | S14: =+S13/R13 -> 501792.11
A15: =+A11+1 -> 9 | B15: Q345 | C15: 7.85
A16: II | B16: INOX | O16: 1502.0755
A17: 1 | B17: SUS304 | C17: 7.93 | O17: 94.59093
A18: =+A17+1 -> 2 | B18: SUS316L | C18: 7.93 | O18: 554.48776
A19: =+A18+1 -> 3 | B19: Inox | C19: 7.93 | O19: 11682.549
A20: =+A19+1 -> 4 | B20: … | O20: =+SUM(O16:O19) -> 13833.703
A21: III | B21: NHÔM
A22: 1 | B22: AL | C22: 2.73
A23: =+A22+1 -> 2 | B23: AL6061 | C23: 2.73
A24: =+A23+1 -> 3
A25: =+A24+1 -> 4 | B25: …
A26: IV | B26: ĐỒNG
A27: 1 | B27: CU | C27: 8.9
A28: =+A27+1 -> 2 | B28: …
A29: =+A28+1 -> 3 | B29: …
A30: V | B30: NHỰA
A31: 1 | B31: MC | C31: 1.9
A32: =+A31+1 -> 2 | B32: PA | C32: 1.9
A33: =+A32+1 -> 3 | B33: PU | C33: 1.25
A34: =+A33+1 -> 4 | B34: …
A35: VI | B35: VL KHÁC
A36: 1 | B36: W | C36: 19.1
A37: =+A36+1 -> 2 | B37: Ag | C37: 19.5
A38: =+A37+1 -> 3 | B38: Pb | C38: 11.4
A39: =+A38+1 -> 4 | B39: Zn | C39: 7.3
A40: =+A39+1 -> 5 | B40: Gang trắng | C40: 7.73
...

Sheet THEP HINH
A1: CÔNG THỨC TÍNH KHỐI LƯỢNG, DIỆN TÍCH XUNG QUANH
A2: STT | B2: Quy cách vật tư | D2: S M/C ngang | E2: Chu vi xung quanh OD | F2: Chu vi xung quanh ID | G2: Quy cách phụ
B3: Quy cách | C3: dày
A4: 1 | B4: H900x300 | C4: 28/16 | D4: 30582.2 | E4: 2937.1
A5: =A4+1 -> 2 | B5: H600x300 | C5: 20/12 | D5: 18721.1 | E5: 2329.7
A6: =A5+1 -> 3 | B6: H500x200 | C6: 16/10 | D6: 11225.1 | E6: 1575.7
A7: =A6+1 -> 4 | B7: H300x150 | C7: 9/6.5 | D7: 4678.1 | E7: 1164.7
A8: =A7+1 -> 5 | B8: H250x125 | C8: 9/6 | D8: 3697 | E8: 974.3
A9: =A8+1 -> 6 | B9: H200x200 | C9: 12/08 | D9: 6353.1 | E9: 1161.7
A10: =A9+1 -> 7 | B10: H125x125 | C10: 9/6.5 | D10: 3000.5 | E10: 723.3
A11: =A10+1 -> 8 | B11: H100x100 | C11: 8/6 | D11: 2159 | E11: 574.3
A12: =A11+1 -> 9 | B12: I125x75 | C12: 5.5 | D12: 2043.1 | E12: 502.2
A13: =A12+1 -> 10 | B13: C200x90 | C13: 8 | D13: 3856.5 | E13: 706.9
A14: =A13+1 -> 11 | B14: C200x80 | C14: 7.5 | D14: 3126.2 | E14: 672.5
A15: =A14+1 -> 12 | B15: C160x65 | C15: 7.2 | D15: 2325 | E15: 544.4
A16: =A15+1 -> 13 | B16: C140x60 | C16: 6.7 | D16: 1918 | E16: 487
A17: =A16+1 -> 14 | B17: C150x75 | C17: 6.5 | D17: 2366.7 | E17: 557.4
A18: =A17+1 -> 15 | B18: C125x65 | C18: 6 | D18: 1708 | E18: 473.1
A19: =A18+1 -> 16 | B19: C125x65 | C19: 5 | D19: 1188.9 | E19: 369.4
A20: =A19+1 -> 17 | B20: C80x45 | C20: 5.5 | D20: 1048.6 | E20: 313.1
A21: =A20+1 -> 18 | B21: C75x40 | C21: 5 | D21: 878.9 | E21: 282.4
A22: =A21+1 -> 19 | B22: L125x75 | C22: 7 | D22: 1361.8 | E22: 391.5
A23: =A22+1 -> 20 | B23: L100x100 | C23: 10 | D23: 1888 | E23: 386.3
... A52: =A51+1 -> 49 | B52: SQ150x150 | C52: 4 | D52: 2294.8 | E52: 586.3
A53: =A52+1 -> 50 | B53: H150x150 | C53: 6x8 | D53: 3259 | E53: 874.3
A54: =A53+1 -> 51 | B54: H150x150 | C54: 7/10 | D54: 3965 | E54: 872.3
A55: =A54+1 -> 52 | B55: H200x100 | C55: 5.5x8 | D55: 2667 | E55: 775.3
A56: =A55+1 -> 53 | B56: SQ100x100 | C56: 5 | D56: 1835.6 | E56: 382.9
A57: =A56+1 -> 54 | B57: SQ200x200 | C57: 6 | D57: 4563.3 | E57: 779.4
A58: =A57+1 -> 55 | B58: SQ40x40 | C58: 2 | D58: 293.7 | E58: 153.2
A59: =A58+1 -> 56 | B59: SQ40x20 | C59: 1.2 | D59: 134.6 | E59: 115.9
A60: =A59+1 -> 57 | B60: SQ40x20 | C60: 2 | D60: 213.7 | E60: 113.1
A61: =A60+1 -> 58 | B61: SQ60x30 | C61: 1.4 | D61: 239.1 | E61: 175.2
A62: =A61+1 -> 59 | B62: V40x40 | C62: 4 | D62: 304.9 | E62: 154
A63: =A62+1 -> 60 | B63: SQ15x15 | C63: 1.5 | D63: 75.2 | E63: 54.9
A64: =A63+1 -> 61 | B64: SQ25x25x1.5 | C64: 1.5 | D64: 135.2 | E64: 94.9
A65: =A64+1 -> 62 | B65: SQ20x20 | C65: 1.5 | D65: 105.2 | E65: 74.9
A66: =A65+1 -> 63 | B66: SQ50x50 | C66: 1.5 | D66: 285.2 | E66: 194.9
A67: =A66+1 -> 64 | B67: V50x50 | C67: 4 | D67: 289.2 | E67: 194.63
... A75: =A74+1 -> 72 | B75: L75x75 | C75: 9 | D75: 1269.1 | E75: 291.2
...

Sheet VT PHU XDG
A1: ĐỊNH MỨC VẬT TƯ PHỤ XƯỞNG ĐỒ GÁ
A2: TÊN VẬT TƯ PHỤ | B2: ĐVT | C2: Hệ số trung bình/ giờ
A4: Mũi dao phay SEKN 1203 AFTN-HPN TT7080 | B4: Mũi | C4: 0.52884615
A5: Mũi dao tiện ngoài 80 độ (WNMG080408MD-4T 750) | B5: Mũi | C5: 0.21153846
A6: EXMT090408E 4T750 | B6: Mũi | C6: 0.052884615
A7: Mũi dao vát mép PLY-000282 SEMT13 | B7: Mũi | C7: 0.052884615
A8: Mũi dao vát mép PLY-000395 LPEX 19 206900 | B8: Mũi | C8: 0.052884615
A9: Mũi dao tiện ngoài 80 độ (WNMG080408MD-4T 750) | B9: Mũi | C9: 0.10576923
A10: EXMT090408E 4T750 | B10: Mũi | C10: 0.052884615
A11: Mũi dao doa (màu nâu đỏ) TPMT11024-PST9115 | B11: Mũi | C11: 0.052884615
A12: Mũi dao vát mép PLY-000395 LPEX 19 206900 | B12: Mũi | C12: 0.052884615
A13: Mũi dao tiện 55 độ DCMT11T308E-4T A04030 ( đức) | B13: Mũi | C13: 0.052884615
A14: Mũi dao tiện lỗ DCGT11T302E-4TA04030 | B14: Mũi | C14: 0.052884615
A15: Mũi dao vát mép PLY-000282 SEMT13 | B15: Mũi | C15: 0.052884615
A16: Mũi dao vát mép PLY-000395 LPEX 19 206900 | B16: Mũi | C16: 0.052884615
A17: Hệ số trung bình mũi dao | C17: =AVERAGEA(C4:C16) -> 0.10576923
A18: Dầu Diezel | B18: Lít | C18: 0.026442308
A19: Đá cắt phi 100 | B19: Viên | C19: 0.21153846
A20: Dây hàn Mig 1.0 ( 15kg/cuộn) | B20: Kg | C20: 0.010576923
A21: Nhám xếp King Dom | B21: Cái | C21: 0.26442308
A22: Cọ sơn 10 phân | B22: Cây | C22: 0.10576923
A23: Chổi đót | B23: Cây | C23: 0.052884615
A24: Vải lau | B24: Kg | C24: 0.052884615
A25: Khóa việt tiệp 38 | B25: Ổ | C25: 0.026442308
A26: Kính chống bụi | B26: Cái | C26: 0.15865385
A27: Khẩu trang 3M | B27: Cái | C27: 0.15865385
A29: Ghi chú: - Lấy thời gian gia công chi tiết quy đổi về mũi dao và vật tư phụ.

Sheet VT PHU CNC
A1: ĐỊNH MỨC VẬT TƯ DAO CỤ XƯỞNG CNC
A3: STT | B3: MSTS | C3: Tên máy | D3: Mũi daotb/giờ
A5: Phay CNC
A6: 1 | B6: ATM-C1303-331 | C6: Máy phay Makino CNC | D6: 0.03875969
A7: =+A6+1 -> 2 | B7: ATM-C1303A-1240 | C7: Máy phay kim loại CNC -Model TR-60A | D7: 0.018087855
A8: =+A7+1 -> 3 | B8: ATM-C1303A-1403 | C8: Máy phay kim loại CNC Model TR-60A | D8: 0.041343669
A9: =+A8+1 -> 4 | B9: ATM-C1303A-1402 | C9: Máy phay kim loại CNC Model TR-60A | D9: 0.041343669
A10: =+A9+1 -> 5 | B10: ATM-C1303-332 | C10: Máy phay khoan Fanuc CNC | D10: 0.007751938
A11: Trung bình mũi dao phay CNC | D11: =AVERAGEA(D6:D10) -> 0.029457364
A12: Tiện CNC
A13: 6 | B13: ATM-C1303A-1242 | C13: Máy tiện kim loại CNC -Model CPL-106 | D13: 0.041343669
A14: =+A13+1 -> 7 | B14: ATM-C1301-290 | C14: Máy tiện tự động CNC | D14: 0.049095607
A15: =+A14+1 -> 8 | B15: ATM-C1303A-1306 | C15: Máy tiện kim loại CNC Model CPL-106 | D15: 0.072351421
A16: =+A15+1 -> 9 | B16: ATM-C1303-812 | C16: Máy tiện CNC Ikegai | D16: 0.012919897
A17: =+A16+1 -> 10 | B17: ATM-C1303A-1241 | C17: Máy tiện kim loại CNC -Model CPL-106 | D17: 0.14211886
A18: =+A17+1 -> 11 | B18: ATM-C1303-369 | C18: May tiện Wasino OT CNC | D18: 0.10594315
A19: =+A18+1 -> 12 | B19: ATM-C1303A-1307 | C19: Máy tiện kim loại CNC Model CPL-106 | D19: 0.098191214
A20: =+A19+1 -> 13 | B20: ATM-C1303-370 | C20: May tiện Wasino 21T CNC | D20: 0.082687339
A21: =+A20+1 -> 14 | B21: ATM-C1303-729 | C21: Máy tiện CNC Moriseiki | D21: 0.064599483
A22: =+A21+1 -> 15 | B22: ATM-C1303-781 | C22: Máy tiện CNC Moriseiki | D22: 0.095607235
A23: =+A22+1 -> 16 | B23: ATM-C1303-950 | C23: Máy tiện CNC Moriseiki | D23: 0.093023256
A24: =+A23+1 -> 17 | B24: ATM-C1303A-1335 | C24: Máy tiện ngang kim loại CNC Model CPL-30 MC | D24: 0.16795866
A25: =+A24+1 -> 18 | B25: ATM-C1303A-1303 | C25: Máy tiện kim loại CNC Model CPL-3512 | D25: 0.1369509
... A27: =+A26+1 -> 20 | B27: MÁY MỚI 02 | C27: Máy phay kim loại CNC Model TR-60A | D27: 0.031007752
A28: Trung bình mũi dao tiện CNC | D28: =AVERAGEA(D13:D27) -> 0.081653747
A30: Ghi chú: - Lấy thời gian gia công chi tiết quy đổi về mũi dao.
