Workbook
Name _: "SQRT"
Name __________________________NSO2: {"'Sheet1'!$L$16"}
Name __________________________NSO2: {"'Sheet1'!$L$16"}
Name __________________________NSO2: {"'Sheet1'!$L$16"}
Name _________________________NSO2: {"'Sheet1'!$L$16"}
Name _________________________NSO2: {"'Sheet1'!$L$16"}
Name _________________________NSO2: {"'Sheet1'!$L$16"}
Name ________________________NSO2: {"'Sheet1'!$L$16"}
Name ________________________NSO2: {"'Sheet1'!$L$16"}
Name ________________________NSO2: {"'Sheet1'!$L$16"}
Name _______________________f5: {"'Sheet1'!$L$16"}
Name _______________________f5: {"'Sheet1'!$L$16"}
Name _______________________f5: {"'Sheet1'!$L$16"}
Name _______________________NSO2: {"'Sheet1'!$L$16"}
Name _______________________NSO2: {"'Sheet1'!$L$16"}
Name _______________________NSO2: {"'Sheet1'!$L$16"}
Name ______________________f5: {"'Sheet1'!$L$16"}
Name ______________________f5: {"'Sheet1'!$L$16"}
Name ______________________f5: {"'Sheet1'!$L$16"}
Name ______________________NSO2: {"'Sheet1'!$L$16"}
Name ______________________NSO2: {"'Sheet1'!$L$16"}
Name ______________________NSO2: {"'Sheet1'!$L$16"}
Name _____________________f5: {"'Sheet1'!$L$16"}
Name _____________________f5: {"'Sheet1'!$L$16"}
Name _____________________f5: {"'Sheet1'!$L$16"}
Name _____________________NSO2: {"'Sheet1'!$L$16"}
Name _____________________NSO2: {"'Sheet1'!$L$16"}
Name _____________________NSO2: {"'Sheet1'!$L$16"}
Name ____________________f5: {"'Sheet1'!$L$16"}
Name ____________________f5: {"'Sheet1'!$L$16"}
Name ____________________f5: {"'Sheet1'!$L$16"}
Name ____________________NSO2: {"'Sheet1'!$L$16"}
Name ____________________NSO2: {"'Sheet1'!$L$16"}
Name ____________________NSO2: {"'Sheet1'!$L$16"}
Name ___________________f5: {"'Sheet1'!$L$16"}
Name ___________________f5: {"'Sheet1'!$L$16"}
Name ___________________f5: {"'Sheet1'!$L$16"}
Name ___________________NSO2: {"'Sheet1'!$L$16"}
Name ___________________NSO2: {"'Sheet1'!$L$16"}
Name ___________________NSO2: {"'Sheet1'!$L$16"}
Name __________________f5: {"'Sheet1'!$L$16"}
Name __________________f5: {"'Sheet1'!$L$16"}
Name __________________f5: {"'Sheet1'!$L$16"}
Name __________________NSO2: {"'Sheet1'!$L$16"}
Name __________________NSO2: {"'Sheet1'!$L$16"}
Name __________________NSO2: {"'Sheet1'!$L$16"}
Name _________________f5: {"'Sheet1'!$L$16"}
Name _________________f5: {"'Sheet1'!$L$16"}
Name _________________f5: {"'Sheet1'!$L$16"}
Name _________________NSO2: {"'Sheet1'!$L$16"}
Name _________________NSO2: {"'Sheet1'!$L$16"}
Name _________________NSO2: {"'Sheet1'!$L$16"}
Name ________________f5: {"'Sheet1'!$L$16"}
Name ________________f5: {"'Sheet1'!$L$16"}
Name ________________f5: {"'Sheet1'!$L$16"}
Name ________________NSO2: {"'Sheet1'!$L$16"}
Name ________________NSO2: {"'Sheet1'!$L$16"}
Name ________________NSO2: {"'Sheet1'!$L$16"}
Name _______________f5: {"'Sheet1'!$L$16"}
Name _______________f5: {"'Sheet1'!$L$16"}

Sheet KL RIENG
A1: KHỐI LƯỢNG RIÊNG VẬT LIỆU
A2: STT | B2: VẬT LIỆU | C2: KL RIÊNG (kg/dm3)
A3: I | B3: THÉP
A4: 1 | B4: SPHC | C4: 7.85
A5: =+A4+1 -> 2 | B5: SPCC | C5: 7.85
A6: =+A5+1 -> 3 | B6: SS400 | C6: 7.85
A7: =+A6+1 -> 4 | B7: C45 | C7: 7.85
A8: =+A7+1 -> 5 | B8: CT380 | C8: 7.85
A9: =+A8+1 -> 6 | B9: SKD11 | C9: 7.85
A10: =+A9+1 -> 7 | B10: SKD61 | C10: 7.85
A11: =+A10+1 -> 8 | B11: S355 | C11: 7.85
A12: =+A11+1 -> 9
A13: =+A12+1 -> 10
A14: =+A13+1 -> 11
A15: =+A14+1 -> 12
A16: =+A15+1 -> 13
A17: =+A16+1 -> 14
A18: =+A17+1 -> 15
A19: II | B19: INOX
A20: 1 | B20: SUS304 | C20: 7.93
A21: =+A20+1 -> 2 | B21: SUS430 | C21: 7.93
A22: =+A21+1 -> 3 | B22: …
A23: =+A22+1 -> 4 | B23: …
A24: III | B24: NHÔM
A25: 1 | B25: AL | C25: 2.73
A26: =+A25+1 -> 2 | B26: AL6061 | C26: 2.73
A27: =+A26+1 -> 3 | B27: …
A28: =+A27+1 -> 4 | B28: …
A29: IV | B29: ĐỒNG
A30: 1 | B30: CU | C30: 8.9
A31: =+A30+1 -> 2 | B31: …
A32: =+A31+1 -> 3 | B32: …
A33: V | B33: NHỰA
A34: 1 | B34: MC | C34: 1.9
A35: =+A34+1 -> 2 | B35: PA | C35: 1.9
A36: =+A35+1 -> 3 | B36: POM | C36: 1.9
A37: =+A36+1 -> 4 | B37: …
A38: VI | B38: VL KHÁC
A39: 1 | B39: W | C39: 19.1
A40: =+A39+1 -> 2 | B40: Ag | C40: 19.5
...

Sheet THEP HINH
A1: KHỐI LƯỢNG, DIỆN TÍCH XUNG QUANH
A2: STT | B2: Quy cách vật tư | D2: S M/C ngang (mm2) | E2: Chu vi xung quanh OD (mm) | F2: Chu vi xung quanh ID | G2: Quy cách chung | H2: Mã
B3: Quy cách | C3: dày
A4: I | B4: CHANNEL
A5: 1 | B5: C40x25x2.5 | C5: 2.5 | D5: 210 | E5: 146.4 | G5: C40x25 | H5: =IF(B5<>0,"TH","") -> TH
A6: =+A5+1 -> 2 | B6: C50x25x3 | C6: 3 | D6: 376.6 | E6: 180.9 | G6: C50x25 | H6: =IF(B6<>0,"TH","") -> TH
A7: =+A6+1 -> 3 | B7: C65x32x4/6 | C7: 4/6 | D7: 608 | E7: 230 | G7: C65x32 | H7: =IF(B7<>0,"TH","") -> TH
A8: =+A7+1 -> 4 | B8: C75x40x5/7 | C8: 5/7 | D8: 881 | E8: 282.4 | G8: C75x40 | H8: =IF(B8<>0,"TH","") -> TH
A9: =+A8+1 -> 5 | B9: C80x40x5 | C9: 5 | D9: 975.45 | E9: 293.1 | G9: C80x40 | H9: =IF(B9<>0,"TH","") -> TH
A10: =+A9+1 -> 6 | B10: C80x45x5.5 | C10: 5.5 | D10: 1048.6 | E10: 313.1 | G10: C80x45 | H10: =IF(B10<>0,"TH","") -> TH
A11: =+A10+1 -> 7 | B11: C100x45x5.3 | C11: 5.3 | D11: 1368.01 | E11: 361.9485 | G11: C100x45 | H11: =IF(B11<>0,"TH","") -> TH
A12: =+A11+1 -> 8 | B12: C100x50x5/7.5 | C12: 5/7.5 | D12: 1188.9 | E12: 369.3 | G12: C100x50 | H12: =IF(B12<>0,"TH","") -> TH
A13: =+A12+1 -> 9 | B13: C120x55x5.5 | C13: 5.5 | D13: 1535.6 | E13: 422.8 | G13: C120x55 | H13: =IF(B13<>0,"TH","") -> TH
A14: =+A13+1 -> 10 | B14: C120x75x5.2 | C14: 5.2 | D14: 1940.26 | E14: 514.69 | G14: C120x75 | H14: =IF(B14<>0,"TH","") -> TH
A15: =+A14+1 -> 11 | B15: C125x65x6/8 | C15: 6/8 | D15: 1708 | E15: 473.1 | G15: C125x65 | H15: =IF(B15<>0,"TH","") -> TH
A16: =+A15+1 -> 12 | B16: C140x60x6.7 | C16: 6.7 | D16: 1918 | E16: 487 | G16: C140x60 | H16: =IF(B16<>0,"TH","") -> TH
A17: =+A16+1 -> 13 | B17: C150x70x6/8.5 | C17: 6/8.5 | D17: 2009 | E17: 544 | G17: C150x70 | H17: =IF(B17<>0,"TH","") -> TH
A18: =+A17+1 -> 14 | B18: C150x75x6.5/10 | C18: 6.5/10 | D18: 2366.7 | E18: 557.4 | G18: C150x75 | H18: =IF(B18<>0,"TH","") -> TH
A19: =+A18+1 -> 15 | B19: C150x75x9/12 | C19: 9/12 | D19: 3059 | E19: 520 | G19: C150x75 | H19: =IF(B19<>0,"TH","") -> TH
A20: =+A19+1 -> 16 | B20: C160x65x4.8 | C20: 4.8 | D20: 1956.65 | E20: 541.48 | G20: C160x65 | H20: =IF(B20<>0,"TH","") -> TH
A21: =+A20+1 -> 17 | B21: C160x65x7.2 | C21: 7.2 | D21: 2325 | E21: 544.4 | G21: C160x65 | H21: =IF(B21<>0,"TH","") -> TH
A22: =+A21+1 -> 18 | B22: C180x70x8 | C22: 8 | D22: 2832 | E22: 597.7 | G22: C180x70 | H22: =IF(B22<>0,"TH","") -> TH
A23: =+A22+1 -> 19 | B23: C180x75x7/10.5 | C23: 7/10.5 | D23: 2720 | E23: 616 | G23: C180x75 | H23: =IF(B23<>0,"TH","") -> TH
A24: =+A23+1 -> 20 | B24: C180x90x7.5/12.5 | C24: 7.5/12.5 | D24: 3457 | E24: 668 | G24: C180x90 | H24: =IF(B24<>0,"TH","") -> TH
A25: =+A24+1 -> 21 | B25: C200x75x8.2 | C25: 8.2 | D25: 3212.55 | E25: 658.24 | G25: C200x75 | H25: =IF(B25<>0,"TH","") -> TH
A26: =+A25+1 -> 22 | B26: C200x80x7.5/11 | C26: 7.5/11 | D26: 3126.2 | E26: 672.5 | G26: C200x80 | H26: =IF(B26<>0,"TH","") -> TH
A27: =+A26+1 -> 23 | B27: C200x90x8/13.5 | C27: 8/13.5 | D27: 3856.5 | E27: 706.9 | G27: C200x90 | H27: =IF(B27<>0,"TH","") -> TH
A28: =+A27+1 -> 24 | B28: C220x77x7/11.5 | C28: 7/11.5 | D28: 3184 | E28: 702 | G28: C220x77 | H28: =IF(B28<>0,"TH","") -> TH
A29: =+A28+1 -> 25 | B29: C250x80x8/12.5 | C29: 8/12.5 | D29: 3851 | E29: 764 | G29: C250x80 | H29: =IF(B29<>0,"TH","") -> TH
A30: =+A29+1 -> 26 | B30: C250x75x25x4.8 | C30: 4.8 | D30: 2008.51 | E30: 846.48 | G30: C250x75x25 | H30: =IF(B30<>0,"TH","") -> TH
A31: =+A30+1 -> 27 | B31: C250x90x9/13 | C31: 9/13 | D31: 4407 | E31: 805.11 | G31: C250x90 | H31: =IF(B31<>0,"TH","") -> TH
A32: =+A31+1 -> 28 | B32: C250x90x11/14.5 | C32: 11/14.5 | D32: 5117 | E32: 792 | G32: C250x90 | H32: =IF(B32<>0,"TH","") -> TH
A33: =+A32+1 -> 29 | B33: C280x100x9/13 | C33: 9/13 | D33: 4937 | E33: 904 | G33: C280x100 | H33: =IF(B33<>0,"TH","") -> TH
A34: =+A33+1 -> 30 | B34: C280x100x11.5/16 | C34: 11.5/16 | D34: 6137 | E34: 888 | G34: C280x100 | H34: =IF(B34<>0,"TH","") -> TH
A35: =+A34+1 -> 31 | B35: C300x90x9/13 | C35: 9/13 | D35: 4857 | E35: 904 | G35: C300x90 | H35: =IF(B35<>0,"TH","") -> TH
A36: =+A35+1 -> 32 | B36: C300x90x10/15.5 | C36: 10/15.5 | D36: 5574 | E36: 884 | G36: C300x90 | H36: =IF(B36<>0,"TH","") -> TH
A37: =+A36+1 -> 33 | B37: C300x90x12/16 | C37: 12/16 | D37: 6190 | E37: 884 | G37: C300x90 | H37: =IF(B37<>0,"TH","") -> TH
A38: =+A37+1 -> 34 | B38: C380x100x10.5/16 | C38: 10.5/16 | D38: 6939 | E38: 1088 | G38: C380x100 | H38: =IF(B38<>0,"TH","") -> TH
A39: =+A38+1 -> 35 | B39: C380x100x13/16.5 | C39: 13/16.5 | D39: 7896 | E39: 1088 | G39: C380x100 | H39: =IF(B39<>0,"TH","") -> TH
A40: =+A39+1 -> 36 | B40: C380x100x13/20 | C40: 13/20 | D40: 8571 | E40: 1064 | G40: C380x100 | H40: =IF(B40<>0,"TH","") -> TH
...

Sheet Bieu mau
G1: ĐỊNH MỨC VẬT TƯ CƠ KHÍ HẠNG MỤC: ----------
A5: Đơn hàng:
A6: Mã hóa -------:
A7: Lần ban hành:
A9: STT | B9: THÔNG TIN CHI TIẾT | N9: ĐỊNH MỨC | Q9: THÔNG TIN BÁO GIÁ | Y9: ED đen, xi mạ, Sơn | Z9: NGUỒN GỐC | AC9: Ghi chú
B10: Cấp độ | F10: Tên chi tiết | G10: Mã số | H10: Vật liệu | I10: Quy cách chi tiết | N10: ĐVT | O10: Số lượng | Q10: Hình ảnh | R10: KL/ct (Kg) | S10: KL/Bộ (Kg) | T10: Tổng KL/ ĐH (Kg) | U10: KL phôi thành phẩm (BV 3D) (Kg) | V10: Diện tích nhúng ED (m2) | W10: Diện tích sơn (m2) | X10: Mô tả sơ bộ công đoạn gia công | Z10: THACO | AA10: Mua ngoài | AB10: Khách hàng cấp
B11: 1 | C11: 2 | D11: 3 | E11: 4 | I11: Dài | J11: Rộng | K11: Dày | L11: Od | M11: ld | O11: SL/bộ | P11: SL/ĐH
R12: =IFERROR(IFERROR(IF(MID(J12,3,1)="x",(LEFT(J12,2)*2+RIGHT(J12,2)*2-2*4*K12)*K12*I12*VLOOKUP(H12,'KL RIENG'!$B$3:$C$48,2,0)*10^-6,IF(AND(L12<>0,I12<>0,M12="",K12=""),(L12*L12*3.14/4)*I12*VLOOKUP(H12,'KL RIENG'!$B$2:$C$48,2,0)*10^-6,IF(AND(L12<>0,K12<>0,M12="",I12=""),(3.14/4)*L12*L12*K12*VLOOKUP(H12,'KL RIENG'!$B$2:$C$48,2,0)*10^-6,IF(AND(L12<>0,K12<>0,M12<>0,I12=""),(3.14/4)*(L12*L12-M12*M12)*K12*VLOOKUP(H12,'KL RIENG'!$B$2:$C$48,2,0)*10^-6,IF(AND(I12<>0,K12<>0,L12<>0,M12=""),(L12*L12-(L12-2*K12)*(L12-2*K12))*3.14/4*I12*VLOOKUP(H12,'KL RIENG'!$B$2:$C$48,2,0)*10^-6,IF(AND(I12<>0,K12="",L12<>0,M12<>0),(L12*L12-M12*M12)*3.14/4*I12*VLOOKUP(H12,'KL RIENG'!$B$2:$C$48,2,0)*10^-6,I12*J12*K12*VLOOKUP(H12,'KL RIENG'!$B$2:$C$48,2,0)*10^-6)))))),VLOOKUP(J12,'THEP HINH'!$B$2:$F$287,3,0)*I12*VLOOKUP(H12,'KL RIENG'!$B$2:$C$48,2,0)*10^-6),"") | S12: =IFERROR(IF(R12<>0,R12*O12,VLOOKUP(J12,'THEP HINH'!$B$286:$E$1048576,3,0)*O12),"") -> 0 | T12: =IFERROR(P12*R12,"") -> 0
R13: =IFERROR(IFERROR(IF(MID(J13,3,1)="x",(LEFT(J13,2)*2+RIGHT(J13,2)*2-2*4*K13)*K13*I13*VLOOKUP(H13,'KL RIENG'!$B$3:$C$48,2,0)*10^-6,IF(AND(L13<>0,I13<>0,M13="",K13=""),(L13*L13*3.14/4)*I13*VLOOKUP(H13,'KL RIENG'!$B$2:$C$48,2,0)*10^-6,IF(AND(L13<>0,K13<>0,M13="",I13=""),(3.14/4)*L13*L13*K13*VLOOKUP(H13,'KL RIENG'!$B$2:$C$48,2,0)*10^-6,IF(AND(L13<>0,K13<>0,M13<>0,I13=""),(3.14/4)*(L13*L13-M13*M13)*K13*VLOOKUP(H13,'KL RIENG'!$B$2:$C$48,2,0)*10^-6,IF(AND(I13<>0,K13<>0,L13<>0,M13=""),(L13*L13-(L13-2*K13)*(L13-2*K13))*3.14/4*I13*VLOOKUP(H13,'KL RIENG'!$B$2:$C$48,2,0)*10^-6,IF(AND(I13<>0,K13="",L13<>0,M13<>0),(L13*L13-M13*M13)*3.14/4*I13*VLOOKUP(H13,'KL RIENG'!$B$2:$C$48,2,0)*10^-6,I13*J13*K13*VLOOKUP(H13,'KL RIENG'!$B$2:$C$48,2,0)*10^-6)))))),VLOOKUP(J13,'THEP HINH'!$B$2:$F$287,3,0)*I13*VLOOKUP(H13,'KL RIENG'!$B$2:$C$48,2,0)*10^-6),"") | S13: =IFERROR(IF(R13<>0,R13*O13,VLOOKUP(J13,'THEP HINH'!$B$286:$E$1048576,3,0)*O13),"") -> 0 | T13: =IFERROR(P13*R13,"") -> 0
R14: =IFERROR(IFERROR(IF(MID(J14,3,1)="x",(LEFT(J14,2)*2+RIGHT(J14,2)*2-2*4*K14)*K14*I14*VLOOKUP(H14,'KL RIENG'!$B$3:$C$48,2,0)*10^-6,IF(AND(L14<>0,I14<>0,M14="",K14=""),(L14*L14*3.14/4)*I14*VLOOKUP(H14,'KL RIENG'!$B$2:$C$48,2,0)*10^-6,IF(AND(L14<>0,K14<>0,M14="",I14=""),(3.14/4)*L14*L14*K14*VLOOKUP(H14,'KL RIENG'!$B$2:$C$48,2,0)*10^-6,IF(AND(L14<>0,K14<>0,M14<>0,I14=""),(3.14/4)*(L14*L14-M14*M14)*K14*VLOOKUP(H14,'KL RIENG'!$B$2:$C$48,2,0)*10^-6,IF(AND(I14<>0,K14<>0,L14<>0,M14=""),(L14*L14-(L14-2*K14)*(L14-2*K14))*3.14/4*I14*VLOOKUP(H14,'KL RIENG'!$B$2:$C$48,2,0)*10^-6,IF(AND(I14<>0,K14="",L14<>0,M14<>0),(L14*L14-M14*M14)*3.14/4*I14*VLOOKUP(H14,'KL RIENG'!$B$2:$C$48,2,0)*10^-6,I14*J14*K14*VLOOKUP(H14,'KL RIENG'!$B$2:$C$48,2,0)*10^-6)))))),VLOOKUP(J14,'THEP HINH'!$B$2:$F$287,3,0)*I14*VLOOKUP(H14,'KL RIENG'!$B$2:$C$48,2,0)*10^-6),"") | S14: =IFERROR(IF(R14<>0,R14*O14,VLOOKUP(J14,'THEP HINH'!$B$286:$E$1048576,3,0)*O14),"") -> 0 | T14: =IFERROR(P14*R14,"") -> 0
R15: =IFERROR(IFERROR(IF(MID(J15,3,1)="x",(LEFT(J15,2)*2+RIGHT(J15,2)*2-2*4*K15)*K15*I15*VLOOKUP(H15,'KL RIENG'!$B$3:$C$48,2,0)*10^-6,IF(AND(L15<>0,I15<>0,M15="",K15=""),(L15*L15*3.14/4)*I15*VLOOKUP(H15,'KL RIENG'!$B$2:$C$48,2,0)*10^-6,IF(AND(L15<>0,K15<>0,M15="",I15=""),(3.14/4)*L15*L15*K15*VLOOKUP(H15,'KL RIENG'!$B$2:$C$48,2,0)*10^-6,IF(AND(L15<>0,K15<>0,M15<>0,I15=""),(3.14/4)*(L15*L15-M15*M15)*K15*VLOOKUP(H15,'KL RIENG'!$B$2:$C$48,2,0)*10^-6,IF(AND(I15<>0,K15<>0,L15<>0,M15=""),(L15*L15-(L15-2*K15)*(L15-2*K15))*3.14/4*I15*VLOOKUP(H15,'KL RIENG'!$B$2:$C$48,2,0)*10^-6,IF(AND(I15<>0,K15="",L15<>0,M15<>0),(L15*L15-M15*M15)*3.14/4*I15*VLOOKUP(H15,'KL RIENG'!$B$2:$C$48,2,0)*10^-6,I15*J15*K15*VLOOKUP(H15,'KL RIENG'!$B$2:$C$48,2,0)*10^-6)))))),VLOOKUP(J15,'THEP HINH'!$B$2:$F$287,3,0)*I15*VLOOKUP(H15,'KL RIENG'!$B$2:$C$48,2,0)*10^-6),"") | S15: =IFERROR(IF(R15<>0,R15*O15,VLOOKUP(J15,'THEP HINH'!$B$286:$E$1048576,3,0)*O15),"") -> 0 | T15: =IFERROR(P15*R15,"") -> 0
R16: =IFERROR(IFERROR(IF(MID(J16,3,1)="x",(LEFT(J16,2)*2+RIGHT(J16,2)*2-2*4*K16)*K16*I16*VLOOKUP(H16,'KL RIENG'!$B$3:$C$48,2,0)*10^-6,IF(AND(L16<>0,I16<>0,M16="",K16=""),(L16*L16*3.14/4)*I16*VLOOKUP(H16,'KL RIENG'!$B$2:$C$48,2,0)*10^-6,IF(AND(L16<>0,K16<>0,M16="",I16=""),(3.14/4)*L16*L16*K16*VLOOKUP(H16,'KL RIENG'!$B$2:$C$48,2,0)*10^-6,IF(AND(L16<>0,K16<>0,M16<>0,I16=""),(3.14/4)*(L16*L16-M16*M16)*K16*VLOOKUP(H16,'KL RIENG'!$B$2:$C$48,2,0)*10^-6,IF(AND(I16<>0,K16<>0,L16<>0,M16=""),(L16*L16-(L16-2*K16)*(L16-2*K16))*3.14/4*I16*VLOOKUP(H16,'KL RIENG'!$B$2:$C$48,2,0)*10^-6,IF(AND(I16<>0,K16="",L16<>0,M16<>0),(L16*L16-M16*M16)*3.14/4*I16*VLOOKUP(H16,'KL RIENG'!$B$2:$C$48,2,0)*10^-6,I16*J16*K16*VLOOKUP(H16,'KL RIENG'!$B$2:$C$48,2,0)*10^-6)))))),VLOOKUP(J16,'THEP HINH'!$B$2:$F$287,3,0)*I16*VLOOKUP(H16,'KL RIENG'!$B$2:$C$48,2,0)*10^-6),"") | S16: =IFERROR(IF(R16<>0,R16*O16,VLOOKUP(J16,'THEP HINH'!$B$286:$E$1048576,3,0)*O16),"") -> 0 | T16: =IFERROR(P16*R16,"") -> 0
R17: =IFERROR(IFERROR(IF(MID(J17,3,1)="x",(LEFT(J17,2)*2+RIGHT(J17,2)*2-2*4*K17)*K17*I17*VLOOKUP(H17,'KL RIENG'!$B$3:$C$48,2,0)*10^-6,IF(AND(L17<>0,I17<>0,M17="",K17=""),(L17*L17*3.14/4)*I17*VLOOKUP(H17,'KL RIENG'!$B$2:$C$48,2,0)*10^-6,IF(AND(L17<>0,K17<>0,M17="",I17=""),(3.14/4)*L17*L17*K17*VLOOKUP(H17,'KL RIENG'!$B$2:$C$48,2,0)*10^-6,IF(AND(L17<>0,K17<>0,M17<>0,I17=""),(3.14/4)*(L17*L17-M17*M17)*K17*VLOOKUP(H17,'KL RIENG'!$B$2:$C$48,2,0)*10^-6,IF(AND(I17<>0,K17<>0,L17<>0,M17=""),(L17*L17-(L17-2*K17)*(L17-2*K17))*3.14/4*I17*VLOOKUP(H17,'KL RIENG'!$B$2:$C$48,2,0)*10^-6,IF(AND(I17<>0,K17="",L17<>0,M17<>0),(L17*L17-M17*M17)*3.14/4*I17*VLOOKUP(H17,'KL RIENG'!$B$2:$C$48,2,0)*10^-6,I17*J17*K17*VLOOKUP(H17,'KL RIENG'!$B$2:$C$48,2,0)*10^-6)))))),VLOOKUP(J17,'THEP HINH'!$B$2:$F$287,3,0)*I17*VLOOKUP(H17,'KL RIENG'!$B$2:$C$48,2,0)*10^-6),"") | S17: =IFERROR(IF(R17<>0,R17*O17,VLOOKUP(J17,'THEP HINH'!$B$286:$E$1048576,3,0)*O17),"") -> 0 | T17: =IFERROR(P17*R17,"") -> 0
R18: =IFERROR(IFERROR(IF(MID(J18,3,1)="x",(LEFT(J18,2)*2+RIGHT(J18,2)*2-2*4*K18)*K18*I18*VLOOKUP(H18,'KL RIENG'!$B$3:$C$48,2,0)*10^-6,IF(AND(L18<>0,I18<>0,M18="",K18=""),(L18*L18*3.14/4)*I18*VLOOKUP(H18,'KL RIENG'!$B$2:$C$48,2,0)*10^-6,IF(AND(L18<>0,K18<>0,M18="",I18=""),(3.14/4)*L18*L18*K18*VLOOKUP(H18,'KL RIENG'!$B$2:$C$48,2,0)*10^-6,IF(AND(L18<>0,K18<>0,M18<>0,I18=""),(3.14/4)*(L18*L18-M18*M18)*K18*VLOOKUP(H18,'KL RIENG'!$B$2:$C$48,2,0)*10^-6,IF(AND(I18<>0,K18<>0,L18<>0,M18=""),(L18*L18-(L18-2*K18)*(L18-2*K18))*3.14/4*I18*VLOOKUP(H18,'KL RIENG'!$B$2:$C$48,2,0)*10^-6,IF(AND(I18<>0,K18="",L18<>0,M18<>0),(L18*L18-M18*M18)*3.14/4*I18*VLOOKUP(H18,'KL RIENG'!$B$2:$C$48,2,0)*10^-6,I18*J18*K18*VLOOKUP(H18,'KL RIENG'!$B$2:$C$48,2,0)*10^-6)))))),VLOOKUP(J18,'THEP HINH'!$B$2:$F$287,3,0)*I18*VLOOKUP(H18,'KL RIENG'!$B$2:$C$48,2,0)*10^-6),"") | S18: =IFERROR(IF(R18<>0,R18*O18,VLOOKUP(J18,'THEP HINH'!$B$286:$E$1048576,3,0)*O18),"") -> 0 | T18: =IFERROR(P18*R18,"") -> 0
R19: =IFERROR(IFERROR(IF(MID(J19,3,1)="x",(LEFT(J19,2)*2+RIGHT(J19,2)*2-2*4*K19)*K19*I19*VLOOKUP(H19,'KL RIENG'!$B$3:$C$48,2,0)*10^-6,IF(AND(L19<>0,I19<>0,M19="",K19=""),(L19*L19*3.14/4)*I19*VLOOKUP(H19,'KL RIENG'!$B$2:$C$48,2,0)*10^-6,IF(AND(L19<>0,K19<>0,M19="",I19=""),(3.14/4)*L19*L19*K19*VLOOKUP(H19,'KL RIENG'!$B$2:$C$48,2,0)*10^-6,IF(AND(L19<>0,K19<>0,M19<>0,I19=""),(3.14/4)*(L19*L19-M19*M19)*K19*VLOOKUP(H19,'KL RIENG'!$B$2:$C$48,2,0)*10^-6,IF(AND(I19<>0,K19<>0,L19<>0,M19=""),(L19*L19-(L19-2*K19)*(L19-2*K19))*3.14/4*I19*VLOOKUP(H19,'KL RIENG'!$B$2:$C$48,2,0)*10^-6,IF(AND(I19<>0,K19="",L19<>0,M19<>0),(L19*L19-M19*M19)*3.14/4*I19*VLOOKUP(H19,'KL RIENG'!$B$2:$C$48,2,0)*10^-6,I19*J19*K19*VLOOKUP(H19,'KL RIENG'!$B$2:$C$48,2,0)*10^-6)))))),VLOOKUP(J19,'THEP HINH'!$B$2:$F$287,3,0)*I19*VLOOKUP(H19,'KL RIENG'!$B$2:$C$48,2,0)*10^-6),"") | S19: =IFERROR(IF(R19<>0,R19*O19,VLOOKUP(J19,'THEP HINH'!$B$286:$E$1048576,3,0)*O19),"") -> 0 | T19: =IFERROR(P19*R19,"") -> 0

Sheet Định nghĩa tách báo giá
